using System;
using System.Linq.Expressions;
using System.Reflection;
using System.Linq;

namespace StoryQ.Infrastructure
{
    /// <summary>
    /// Exception-related operations for StoryQ.
    /// </summary>
    internal static class ExceptionHelper
    {
        /// <summary>
        /// Tries to build an "exception builder" by scanning through the list of configured "pending exceptions" and creating a 
        /// Func out of the constructor
        /// </summary>
        /// <returns></returns>
        internal static Func<string, Exception, Exception> CreateExceptionBuilder()
        {
            //todo: add xunit and mbunit

            var config = new[]
                             {
                                 new {Class="Microsoft.VisualStudio.TestTools.UnitTesting.AssertInconclusiveException", Assembly="Microsoft.VisualStudio.QualityTools.UnitTestFramework"},
                                 new {Class="NUnit.Framework.IgnoreException", Assembly="nunit.framework"},
                             };

            foreach (var v in config)
            {
                var assembly = AppDomain.CurrentDomain.GetAssemblies().FirstOrDefault(x=>x.GetName().Name==v.Assembly);
                if(assembly == null) continue;

                Type type = assembly.GetType(v.Class);
                if (type == null) continue;
                var c = type.GetConstructor(new[] { typeof(string), typeof(Exception) });
                if (c == null) continue;
                var pm = Expression.Parameter(typeof(string), "message");
                var pe = Expression.Parameter(typeof(Exception), "exception");
                var e = Expression.New(c, pm, pe);
                return Expression.Lambda<Func<string, Exception, Exception>>(e, pm, pe).Compile();
            }
            return (x, y) => new NotSupportedException("You need to set StoryQ.ExceptionHelper.PendingExceptionBuilder manually in your test setup. See the property's documentation for more info");
        }

        /// <summary>
        /// Uses forbidden .Net information to try and force the exception to keep its stack trace, even when rethrown
        /// http://stackoverflow.com/questions/1009762/how-can-i-rethrow-an-inner-exception-while-maintaining-the-stack-trace-generated/1009888#1009888
        /// </summary>
        /// <param name="ex">The exception to hack</param>
        /// <param name="separator">the message to put between the real stack trace and the new one</param>
        internal static void TryForceStackTracePermanence(Exception ex, string separator)
        {
            try
            {
                FieldInfo remoteStackTraceString = typeof(Exception).GetField("_remoteStackTraceString", BindingFlags.Instance | BindingFlags.NonPublic);
                if (remoteStackTraceString != null)
                {
                    string nl = Environment.NewLine;
                    remoteStackTraceString.SetValue(ex, ex.StackTrace + nl + nl + separator + nl + nl);
                }
            }
            catch
            {
                Console.Out.WriteLine("Failed to save exception stack trace for " + ex);
            }
        }
    }
}